Workbook

Sheet Dashboard
B2: Rendmaw, Creaking Nest
B3: Commander Deck Dashboard & Analytics — Tokens / Artifacts
B5: Key Deck Metrics
B6: Metric | C6: Value
B7: Total Cards | C7: =SUM(Decklist!A4:A92) -> 100
B8: Total Deck Cost (USD) | C8: =SUMPRODUCT(Decklist!A4:A92, Decklist!H4:H92) -> 400.3
B9: Max Mana Value | C9: =MAX(Decklist!E4:E92) -> 9
B10: Avg Mana Value (Spells) | C10: =AVERAGEIF(Decklist!B4:B92, "<>Lands", Decklist!E4:E92) -> 3.203125
B13: Mana Curve
B14: Mana Value | C14: Count
B15: 1 | C15: =SUMIFS(Decklist!A$4:A$92, Decklist!E$4:E$92, B15, Decklist!B$4:B$92, "<>Lands") -> 3
B16: 2 | C16: =SUMIFS(Decklist!A$4:A$92, Decklist!E$4:E$92, B16, Decklist!B$4:B$92, "<>Lands") -> 21
B17: 3 | C17: =SUMIFS(Decklist!A$4:A$92, Decklist!E$4:E$92, B17, Decklist!B$4:B$92, "<>Lands") -> 20
B18: 4 | C18: =SUMIFS(Decklist!A$4:A$92, Decklist!E$4:E$92, B18, Decklist!B$4:B$92, "<>Lands") -> 8
B19: 5 | C19: =SUMIFS(Decklist!A$4:A$92, Decklist!E$4:E$92, B19, Decklist!B$4:B$92, "<>Lands") -> 7
B20: 6 | C20: =SUMIFS(Decklist!A$4:A$92, Decklist!E$4:E$92, B20, Decklist!B$4:B$92, "<>Lands") -> 4
B21: 7 | C21: =SUMIFS(Decklist!A$4:A$92, Decklist!E$4:E$92, B21, Decklist!B$4:B$92, "<>Lands") -> 0
B22: 8 | C22: =SUMIFS(Decklist!A$4:A$92, Decklist!E$4:E$92, B22, Decklist!B$4:B$92, "<>Lands") -> 0
B23: 9 | C23: =SUMIFS(Decklist!A$4:A$92, Decklist!E$4:E$92, B23, Decklist!B$4:B$92, "<>Lands") -> 1
B24: 10 | C24: =SUMIFS(Decklist!A$4:A$92, Decklist!E$4:E$92, B24, Decklist!B$4:B$92, "<>Lands") -> 0
B25: 11 | C25: =SUMIFS(Decklist!A$4:A$92, Decklist!E$4:E$92, B25, Decklist!B$4:B$92, "<>Lands") -> 0
B26: 12 | C26: =SUMIFS(Decklist!A$4:A$92, Decklist!E$4:E$92, B26, Decklist!B$4:B$92, "<>Lands") -> 0
B29: Category Breakdown
B30: Category | C30: Count
B31: Commander | C31: =SUMIF(Decklist!B$4:B$92, B31, Decklist!A$4:A$92) -> 1
B32: Token Makers | C32: =SUMIF(Decklist!B$4:B$92, B32, Decklist!A$4:A$92) -> 10
B33: Token Payoffs | C33: =SUMIF(Decklist!B$4:B$92, B33, Decklist!A$4:A$92) -> 10
B34: Aristocrats & Drain | C34: =SUMIF(Decklist!B$4:B$92, B34, Decklist!A$4:A$92) -> 3
B35: Sacrifice Outlets | C35: =SUMIF(Decklist!B$4:B$92, B35, Decklist!A$4:A$92) -> 3
B36: Ramp & Rocks | C36: =SUMIF(Decklist!B$4:B$92, B36, Decklist!A$4:A$92) -> 11
B37: Removal & Interaction | C37: =SUMIF(Decklist!B$4:B$92, B37, Decklist!A$4:A$92) -> 11
B38: Card Advantage | C38: =SUMIF(Decklist!B$4:B$92, B38, Decklist!A$4:A$92) -> 8
B39: Artifacts Matters | C39: =SUMIF(Decklist!B$4:B$92, B39, Decklist!A$4:A$92) -> 7
B40: Lands | C40: =SUMIF(Decklist!B$4:B$92, B40, Decklist!A$4:A$92) -> 36
B41: Category Breakdown
B42: Category | C42: Count
B43: Creature | C43: =SUMIF(Decklist!D$4:D$92, B43, Decklist!A$4:A$92) -> 36
B44: Instant | C44: =SUMIF(Decklist!D$4:D$92, B44, Decklist!A$4:A$92) -> 7
B45: Sorcery | C45: =SUMIF(Decklist!D$4:D$92, B45, Decklist!A$4:A$92) -> 3
B46: Artifact | C46: =SUMIF(Decklist!D$4:D$92, B46, Decklist!A$4:A$92) -> 7
...

Sheet Decklist
A1: Rendmaw, Creaking Nest — Comprehensive Decklist (Tokens / Artifacts, v12)
A3: Quantity | B3: Category | C3: Card Name | D3: Card Type | E3: Mana Value | F3: Rendmaw Trigger? | G3: Key Card? | H3: Est. Cost (USD) | I3: Collection Status | J3: Notes & Strategy
A4: 1 | B4: Ramp & Rocks | C4: Copper Myr | D4: Creature | E4: 2 | F4: Yes | G4: No | H4: 1 | I4: Ordered | J4: Artifact Creature: Rendmaw trigger that taps for green.
A5: 1 | B5: Card Advantage | C5: Pygmy Kavu | D5: Creature | E5: 4 | G5: No | H5: 1 | I5: Owned | J5: Requested include. NOTE: not a Rendmaw trigger (plain green creature); only draws off opponents' black creatures, so it is the softest card here — easy swap for another trigger later.
A6: 1 | B6: Commander | C6: Rendmaw, Creaking Nest | D6: Creature | E6: 5 | F6: Yes | G6: Yes | H6: 2 | I6: Owned | J6: Artifact Creature 5/5, menace & reach. On ETB and whenever you play a card with 2+ card types, each player makes a goaded 2/2 flying Bird — your Birds must attack opponents, theirs cannot hit you.
A7: 1 | B7: Ramp & Rocks | C7: Arcane Signet | D7: Artifact | E7: 2 | G7: No | H7: 1 | I7: Owned | J7: Two-mana rock that taps for either of your colors.
A8: 1 | B8: Sacrifice Outlets | C8: Ashnod's Altar | D8: Artifact | E8: 3 | G8: Yes | H8: 8 | I8: Owned | J8: Sacrifice any creature for two colorless — fuels explosive turns and combos with token engines.
A9: 1 | B9: Ramp & Rocks | C9: Golgari Signet | D9: Artifact | E9: 2 | G9: No | H9: 2 | I9: Owned | J9: Ramp and fixing in one — filters mana into black and green.
A10: 1 | B10: Token Payoffs | C10: Idol of Oblivion | D10: Artifact | E10: 2 | G10: Yes | H10: 2 | I10: Owned | J10: Two-mana artifact: tap to draw a card any turn you made a token — nearly every turn here. Late game, sacrifice for a 10/10 Eldrazi. Replaces Pitiless Plunderer.
A11: 1 | B11: Token Payoffs | C11: March of the World Ooze | D11: Enchantment | E11: 6 | G11: Yes | H11: 2 | I11: Need | J11: Creatures you control have base power and toughness 6/6 and are Oozes in addition to their other types; whenever an opponent casts a spell on a turn that isn't theirs, create a 3/3 green Elephant. A perpetual Overrun that turns every 2/2 Bird into a 6/6. Replaces Skullclamp, which found a legal 1-toughness target on only 0.35 turns per game.
A12: 1 | B12: Ramp & Rocks | C12: Sol Ring | D12: Artifact | E12: 1 | G12: Yes | H12: 2 | I12: Owned | J12: The best accelerant in the format — two colorless as early as turn one.
A13: 1 | B13: Token Makers | C13: Arasta of the Endless Web | D13: Creature | E13: 4 | F13: Yes | G13: No | H13: 1 | I13: Owned | J13: Enchantment Creature: Rendmaw trigger. A 1/5 reach wall that spawns 1/2 Spiders whenever opponents cast instants/sorceries — fodder that punishes interaction.
A14: 1 | B14: Aristocrats & Drain | C14: Blood Artist | D14: Creature | E14: 2 | G14: Yes | H14: 4 | I14: Owned | J14: Drains a life and gains you one whenever ANY creature dies — the core aristocrats payoff.
A15: 1 | B15: Token Makers | C15: Burnished Hart | D15: Creature | E15: 3 | F15: Yes | G15: No | H15: 1 | I15: Owned | J15: Artifact Creature: triggers Rendmaw, ramps two basics, and sacrifices itself for later value.
A16: 1 | B16: Sacrifice Outlets | C16: Dockside Chef | D16: Creature | E16: 2 | F16: Yes | G16: No | H16: 1 | I16: Owned | J16: Enchantment Creature: Rendmaw trigger plus a repeatable sacrifice-for-a-card outlet — turns your Birds into cards.
A17: 1 | B17: Ramp & Rocks | C17: Dryad of the Ilysian Grove | D17: Creature | E17: 3 | F17: Yes | G17: Yes | H17: 9 | I17: Owned | J17: Enchantment Creature (Rendmaw trigger), 2/4. Extra land drop each turn plus all your lands tap for any color — ramp, perfect fixing, and landfall on a body. Replaces Kodama's Reach.
A18: 1 | B18: Aristocrats & Drain | C18: Erebos, Bleak-Hearted | D18: Creature | E18: 4 | F18: Yes | G18: Yes | H18: 4 | I18: Owned | J18: Enchantment Creature: Rendmaw trigger, drains when your creatures die, and sacrifices them to draw.
A19: 1 | B19: Token Makers | C19: Filigree Familiar | D19: Creature | E19: 3 | F19: Yes | G19: No | H19: 1 | I19: Owned | J19: Artifact Creature: Rendmaw trigger, gains life, and draws a card when sacrificed.
A20: 1 | B20: Artifacts Matters | C20: Foundry Inspector | D20: Creature | E20: 3 | F20: Yes | G20: No | H20: 1 | I20: Owned | J20: Artifact Creature (Rendmaw trigger). Your artifact spells cost {1} less — deploys the artifact swarm (and more triggers) faster. Replaces Bastion of Remembrance.
A21: 1 | B21: Card Advantage | C21: Gloomshrieker | D21: Creature | E21: 3 | F21: Yes | G21: No | H21: 1 | I21: Owned | J21: Enchantment Creature — Cat Beast 2/1 menace (Rendmaw trigger). ETB returns ANY permanent card from your graveyard to hand — recur a dead artifact, token engine, or land. Exiles itself instead of dying. Replaces Cultivate.
A22: 1 | B22: Token Makers | C22: Grave Titan | D22: Creature | E22: 6 | G22: Yes | H22: 7 | I22: Owned | J22: Four Zombie power on cast and again on every attack — a one-card army and top-end threat.
A23: 1 | B23: Token Makers | C23: Grist, the Hunger Tide | D23: Planeswalker | E23: 3 | F23: Yes | G23: Yes | H23: 8 | I23: Owned | J23: Planeswalker that's a creature card everywhere except the battlefield, so casting it (Planeswalker + Creature) triggers Rendmaw. +1: make an Insect and chain off milled Insects. -2: sac a creature to destroy a creature/planeswalker. -5: drain for creatures in your graveyard. Replaces Ogre Slumlord.
A24: 1 | B24: Removal & Interaction | C24: Haywire Mite | D24: Creature | E24: 1 | F24: Yes | G24: Yes | H24: 3 | I24: Owned | J24: Artifact Creature: Rendmaw trigger that sacrifices to exile a problem artifact or enchantment — colorless removal on a body.
A25: 1 | B25: Artifacts Matters | C25: Junk Diver | D25: Creature | E25: 3 | F25: Yes | G25: No | H25: 1 | I25: Owned | J25: Artifact Creature — Bird (Rendmaw trigger), 1/1 flyer. Dies to return an artifact from your graveyard — a flying Myr Retriever, on-theme with your Birds. Replaces Scute Swarm.
A26: 1 | B26: Ramp & Rocks | C26: Leaden Myr | D26: Creature | E26: 2 | F26: Yes | G26: No | H26: 1 | I26: Owned | J26: Artifact Creature: Rendmaw trigger that taps for black.
A27: 1 | B27: Removal & Interaction | C27: Massacre Wurm | D27: Creature | E27: 6 | G27: Yes | H27: 7 | I27: Owned | J27: Gives enemy creatures -2/-2 (sweeps tokens) and drains for each that dies — an asymmetrical wrath.
A28: 1 | B28: Token Payoffs | C28: Metallic Mimic | D28: Creature | E28: 2 | F28: Yes | G28: Yes | H28: 3 | I28: Owned | J28: Artifact Creature — Shapeshifter (Rendmaw trigger). Name 'Bird' as it enters and every Rendmaw Bird arrives as a 3/3 — a permanent anthem baked into your token engine. Replaces Dreadhorde Invasion.
A29: 1 | B29: Card Advantage | C29: Midnight Reaper | D29: Creature | E29: 3 | G29: Yes | H29: 4 | I29: Owned | J29: Draws a card for each nontoken creature you lose — refuels the aristocrats plan.
A30: 1 | B30: Artifacts Matters | C30: Myr Retriever | D30: Creature | E30: 2 | F30: Yes | G30: No | H30: 1 | I30: Owned | J30: Artifact Creature (Rendmaw trigger). Dies to return an artifact from your graveyard — recursion loop with sac outlets. Replaces Dictate of Erebos.
A31: 1 | B31: Token Payoffs | C31: Ohran Frostfang | D31: Creature | E31: 5 | G31: Yes | H31: 9 | I31: Owned | J31: Snow Snake 2/6. Your ATTACKING creatures gain deathtouch (goaded Birds trade up brutally) and you draw a card whenever a creature connects. Huge go-wide combat payoff. Replaces Poison-Tip Archer.
A32: 1 | B32: Token Makers | C32: Ophiomancer | D32: Creature | E32: 3 | G32: Yes | H32: 8 | I32: Owned | J32: A 1/1 deathtouch Snake each upkeep. Endless sac fodder plus deathtouch blockers that deter attacks.
A33: 1 | B33: Ramp & Rocks | C33: Ornithopter of Paradise | D33: Creature | E33: 2 | F33: Yes | G33: No | H33: 1 | I33: Owned | J33: Artifact Creature: Rendmaw trigger and any-color fixing on a 0/2 flyer.
A34: 1 | B34: Ramp & Rocks | C34: Overlord of the Hauntwoods | D34: Creature | E34: 5 | F34: Yes | G34: Yes | H34: 12 | I34: Owned | J34: Enchantment Creature (Rendmaw trigger), 6/5, Impending 4. Creates an 'Everywhere' land token (taps for any color) on enter AND on attack — repeatable ramp/fixing on a huge body. Replaces Izoni.
A35: 1 | B35: Ramp & Rocks | C35: Palladium Myr | D35: Creature | E35: 3 | F35: Yes | G35: No | H35: 1 | I35: Owned | J35: Artifact Creature: Rendmaw trigger that ramps two colorless.
A36: 1 | B36: Ramp & Rocks | C36: Sakura-Tribe Elder | D36: Creature | E36: 2 | G36: Yes | H36: 3 | I36: Owned | J36: Blocks, then sacrifices to ramp — a chump, a sac trigger, and a land all at once.
A37: 1 | B37: Artifacts Matters | C37: Scrap Trawler | D37: Creature | E37: 3 | F37: Yes | G37: No | H37: 2 | I37: Owned | J37: Artifact Creature (Rendmaw trigger). Whenever an artifact you control dies, return a cheaper artifact from your graveyard — a recursion engine with your Treasures, dorks, and sac outlets. Replaces Chatterfang.
A38: 1 | B38: Card Advantage | C38: Shigeki, Jukai Visionary | D38: Creature | E38: 2 | F38: Yes | G38: No | H38: 1 | I38: Owned | J38: Enchantment Creature (Rendmaw trigger). Bounces itself to ramp a land and fill your graveyard; its channel returns nonlegendary cards from the yard. Value + recursion. Replaces Parallel Lives (Primal Vigor kept as your doubler).
A39: 1 | B39: Token Makers | C39: Solemn Simulacrum | D39: Creature | E39: 4 | F39: Yes | G39: No | H39: 4 | I39: Owned | J39: Artifact Creature: Rendmaw trigger, ramps, draws on death, ideal sac fodder.
A40: 1 | B40: Artifacts Matters | C40: Steel Overseer | D40: Creature | E40: 2 | F40: Yes | G40: No | H40: 5 | I40: Owned | J40: Artifact Creature (Rendmaw trigger). Taps to put a +1/+1 counter on EVERY artifact creature you control — a snowballing anthem over your dozen-plus artifact bodies. Straight upgrade over the Manakin it replaces.
A41: 1 | B41: Token Makers | C41: Tendershoot Dryad | D41: Creature | E41: 6 | G41: No | H41: 6 | I41: Owned | J41: A Saproling every upkeep (two after ten permanents) and anthems your whole board.
...
