Workbook

Sheet Decklist
A1: Seluma, Light of Aysen — Comprehensive Decklist (v1)
A3: Quantity | B3: Category | C3: Card Name | D3: Card Type | E3: Mana Value | F3: Colour Identity | G3: Key Card? | H3: Est. Cost (USD) | I3: Collection Status | J3: Notes & Strategy
A4: 1 | B4: Commander | C4: Seluma, Light of Aysen | D4: Creature | E4: 5 | F4: W | G4: Yes | H4: 30 | I4: Needed | J4: Rulebreaker: Angels of any colour identity + any basic lands. Combat damage to a PLAYER reanimates an Angel. Colour identity stays mono-white.
A5: 1 | B5: Angels | C5: Giada, Font of Hope | D5: Creature | E5: 2 | F5: W | G5: Yes | H5: 3 | I5: Needed | J5: Two-mana ramp into Angels and a counter engine. Note her mana is white only - it does not help cast the off-colour Angels.
A6: 1 | B6: Angels | C6: Resplendent Angel | D6: Creature | E6: 3 | F6: W | G6: No | H6: 3 | I6: Needed | J6: Free 4/4 Angel each end step once you gain 5 life.
A7: 1 | B7: Angels | C7: Righteous Valkyrie | D7: Creature | E7: 3 | F7: W | G7: No | H7: 1 | I7: Needed | J7: Anthem plus lifegain engine; turns on Resplendent Angel and Well of Lost Dreams.
A8: 1 | B8: Angels | C8: Youthful Valkyrie | D8: Creature | E8: 3 | F8: W | G8: No | H8: 0.5 | I8: Needed | J8: Curve filler that grows with every other Angel.
A9: 1 | B9: Angels | C9: Linvala, Keeper of Silence | D9: Creature | E9: 4 | F9: W | G9: No | H9: 15 | I9: Needed | J9: Shuts off opposing activated abilities; a fair stax piece on an Angel body.
A10: 1 | B10: Angels | C10: Serra Paragon | D10: Creature | E10: 4 | F10: W | G10: No | H10: 1 | I10: Needed | J10: Recurs a land or a cheap permanent from the yard; extra land drop matters with a 5-colour mana base.
A11: 1 | B11: Angels | C11: Sigarda, Host of Herons | D11: Creature | E11: 4 | F11: GW | G11: No | H11: 5 | I11: Needed | J11: Off-colour Angel. Hexproof plus sacrifice protection against edict and Toxic Deluge decks.
A12: 1 | B12: Angels | C12: Fallen Angel | D12: Creature | E12: 4 | F12: B | G12: Yes | H12: 0.5 | I12: Needed | J12: Off-colour Angel. Free sacrifice outlet - the cheapest way to put Angels in your graveyard for Seluma to rebuy.
A13: 1 | B13: Angels | C13: Aurelia, Exemplar of Justice | D13: Creature | E13: 4 | F13: RW | G13: No | H13: 1 | I13: Needed | J13: Off-colour Angel. Mentor plus haste pump; can push Seluma through for the trigger.
A14: 1 | B14: Angels | C14: Steel Seraph | D14: Creature | E14: 5 | F14: W | G14: No | H14: 1 | I14: Needed | J14: Prototype {1}{W}{W} makes it a 3-drop that grants flying, vigilance or lifelink to Seluma.
A15: 1 | B15: Angels | C15: Archangel Avacyn | D15: Creature | E15: 5 | F15: W | G15: Yes | H15: 6 | I15: Needed | J15: Flash indestructible protects the whole board through a wrath or a targeted kill on Seluma.
... A91: 1 | B91: Lands | C91: Island | D91: Land | E91: 0 | F91: U | G91: No | H91: 0.1 | I91: Needed | J91: Basic Blue exists solely for Atraxa - there is essentially no other blue Angel worth playing.

Sheet Dashboard
B2: Seluma, Light of Aysen
B3: Commander Deck Dashboard & Analytics (v1)
B5: Key Deck Metrics
B6: Metric | C6: Value
B7: Total Cards | C7: =SUM(Decklist!A4:A91) -> 100
B8: Total Deck Cost (USD) | C8: =SUMPRODUCT(Decklist!A4:A91,Decklist!H4:H91) -> 529.7
B9: USD → CAD Rate | C9: 1.4203
B10: Total Deck Cost (CAD) | C10: =C8*$C$9 -> 752.33291
B11: Max Mana Value | C11: =MAX(Decklist!E4:E91) -> 8
B12: Avg Mana Value (Spells) | C12: =AVERAGEIF(Decklist!B4:B91,"<>Lands",Decklist!E4:E91) -> 4.031746
B13: Total Angels | C13: =SUMIF(Decklist!B4:B91,"Angels",Decklist!A4:A91) -> 28
B14: Off-Colour Angels | C14: =SUMIFS(Decklist!A4:A91,Decklist!B4:B91,"Angels",Decklist!F4:F91,"<>W") -> 8
B15: Total Lands | C15: =SUMIF(Decklist!B4:B91,"Lands",Decklist!A4:A91) -> 37
B16: Basic Lands | C16: =SUMIFS(Decklist!A4:A91,Decklist!B4:B91,"Lands",Decklist!J4:J91,"Basic*") -> 17
B17: Any-Colour Sources (lands + rocks) | C17: 13
B18: Cavern / Unclaimed / Courtyard / Ziggurat / City / Confluence / Coliseum / Orchard / Reflecting Pool + Lantern / Relic / Lotus / Fellwar. Manually counted.
B21: Mana Curve
B22: Mana Value | C22: Count
B23: 1 | C23: =SUMIFS(Decklist!A4:A91,Decklist!E4:E91,B23,Decklist!B4:B91,"<>Lands") -> 6
B24: 2 | C24: =SUMIFS(Decklist!A4:A91,Decklist!E4:E91,B24,Decklist!B4:B91,"<>Lands") -> 7
B25: 3 | C25: =SUMIFS(Decklist!A4:A91,Decklist!E4:E91,B25,Decklist!B4:B91,"<>Lands") -> 14
B26: 4 | C26: =SUMIFS(Decklist!A4:A91,Decklist!E4:E91,B26,Decklist!B4:B91,"<>Lands") -> 11
B27: 5 | C27: =SUMIFS(Decklist!A4:A91,Decklist!E4:E91,B27,Decklist!B4:B91,"<>Lands") -> 11
B28: 6 | C28: =SUMIFS(Decklist!A4:A91,Decklist!E4:E91,B28,Decklist!B4:B91,"<>Lands") -> 6
B29: 7 | C29: =SUMIFS(Decklist!A4:A91,Decklist!E4:E91,B29,Decklist!B4:B91,"<>Lands") -> 7
B30: 8 | C30: =SUMIFS(Decklist!A4:A91,Decklist!E4:E91,B30,Decklist!B4:B91,"<>Lands") -> 1
B33: Category Breakdown
B34: Category | C34: Count
B35: Commander | C35: =SUMIF(Decklist!B4:B91,B35,Decklist!A4:A91) -> 1
B36: Angels | C36: =SUMIF(Decklist!B4:B91,B36,Decklist!A4:A91) -> 28
B37: Ramp & Fixing | C37: =SUMIF(Decklist!B4:B91,B37,Decklist!A4:A91) -> 11
B38: Card Advantage | C38: =SUMIF(Decklist!B4:B91,B38,Decklist!A4:A91) -> 4
B39: Removal & Wraths | C39: =SUMIF(Decklist!B4:B91,B39,Decklist!A4:A91) -> 8
B40: Protection & Evasion | C40: =SUMIF(Decklist!B4:B91,B40,Decklist!A4:A91) -> 6
B41: Reanimation & Recursion | C41: =SUMIF(Decklist!B4:B91,B41,Decklist!A4:A91) -> 3
B42: Graveyard Filling | C42: =SUMIF(Decklist!B4:B91,B42,Decklist!A4:A91) -> 2
B43: Lands | C43: =SUMIF(Decklist!B4:B91,B43,Decklist!A4:A91) -> 37
B44: Total | C44: =SUM(C35:C43) -> 100
B47: Card Type Breakdown
B48: Card Type | C48: Count
...
