Workbook

Sheet Decklist
A1: Karlov of the Ghost Council — Comprehensive Decklist (v2)
A3: Quantity | B3: Category | C3: Card Name | D3: Card Type | E3: Mana Value | F3: Colour Identity | G3: Key Card? | H3: Est. Cost (USD) | I3: Collection Status | J3: Notes & Strategy
A4: 1 | B4: Commander | C4: Karlov of the Ghost Council | D4: Creature | E4: 2 | F4: W/B | G4: Yes | H4: 2 | I4: Needed | J4: Grows two counters per life-gain trigger; exile a creature by removing six counters.
A5: 1 | B5: Lifegain Engines | C5: Sorin, Solemn Visitor | D5: Planeswalker | E5: 4 | F5: W/B | G5: No | H5: 5 | I5: Needed | J5: Team-wide lifelink swing turns combat into a pile of Karlov triggers.
A6: 1 | B6: Lifegain Engines | C6: Sorin, Vengeful Bloodlord | D6: Planeswalker | E6: 4 | F6: W/B | G6: Yes | H6: 4 | I6: Needed | J6: Static lifelink for all your creatures; ultimate reanimates from either yard.
A7: 1 | B7: Lifegain Engines | C7: Soul Warden | D7: Creature | E7: 1 | F7: W | G7: No | H7: 1 | I7: Needed | J7: Soul sister: a trigger for every creature entering, yours or theirs.
A8: 1 | B8: Lifegain Engines | C8: Soulmender | D8: Creature | E8: 1 | F8: W | G8: No | H8: 0.25 | I8: Needed | J8: Repeatable one-mana life gain; cheapest way to grow Karlov each turn.
A9: 1 | B9: Lifegain Engines | C9: Soul's Attendant | D9: Creature | E9: 1 | F9: W | G9: No | H9: 0.5 | I9: Needed | J9: Second Soul Warden; doubles up the incidental triggers.
A10: 1 | B10: Protection & Equipment | C10: Mother of Runes | D10: Creature | E10: 1 | F10: W | G10: No | H10: 8 | I10: Needed | J10: Protects Karlov from targeted removal for free every turn.
A11: 1 | B11: Lifegain Payoffs | C11: Serra Ascendant | D11: Creature | E11: 1 | F11: W | G11: No | H11: 6 | I11: Needed | J11: 6/6 lifelink flier for one mana once you are at 30 or more.
A12: 1 | B12: Lifegain Payoffs | C12: Elas il-Kor, Sadistic Pilgrim | D12: Creature | E12: 2 | F12: W/B | G12: No | H12: 4 | I12: Needed | J12: Drains on every opposing death and gains on each of your creatures entering.
A13: 1 | B13: Lifegain Payoffs | C13: Vizkopa Guildmage | D13: Creature | E13: 2 | F13: W/B | G13: Yes | H13: 1 | I13: Needed | J13: Second ability plus any big life gain is a one-card kill with Exquisite Blood.
A14: 1 | B14: Lifegain Payoffs | C14: Blood Artist | D14: Creature | E14: 2 | F14: B | G14: Yes | H14: 2 | I14: Needed | J14: Drains one per creature death; combo piece with Exquisite Blood.
A15: 1 | B15: Lifegain Engines | C15: Suture Priest | D15: Creature | E15: 2 | F15: W | G15: No | H15: 1.5 | I15: Needed | J15: Gain on your creatures, drain on theirs.
... A88: 10 | B88: Lands | C88: Swamp | D88: Land | E88: 0 | F88: B | G88: No | H88: 0.1 | I88: Owned | J88: Basic black source.

Sheet Dashboard
B2: Karlov of the Ghost Council
B3: Orzhov Lifegain & Drain — Commander Deck Dashboard & Analytics (v2)
B5: Key Deck Metrics
B6: Metric | C6: Value
B7: Total Cards | C7: =SUM(Decklist!A4:A150)
B8: Total Deck Cost (USD) | C8: =SUMPRODUCT(Decklist!A4:A150,Decklist!H4:H150)
B9: USD → CAD Rate | C9: 1.4203
B10: Total Deck Cost (CAD) | C10: =C8*$C$9
B11: Max Mana Value | C11: =MAX(Decklist!E4:E150)
B12: Avg Mana Value (Spells) | C12: =AVERAGEIF(Decklist!B4:B150,"<>Lands",Decklist!E4:E150)
B13: Total Lands | C13: =SUMIF(Decklist!B4:B150,"Lands",Decklist!A4:A150)
B14: Basic Lands | C14: =SUMIFS(Decklist!A4:A150,Decklist!B4:B150,"Lands",Decklist!J4:J150,"Basic*")
B15: Lifegain Triggers (Engines + Payoffs) | C15: =SUMIF(Decklist!B4:B150,"Lifegain Engines",Decklist!A4:A150)+SUMIF(Decklist!B4:B150,"Lifegain Payoffs",Decklist!A4:A150)
B16: W/B Dual-Colour Cards | C16: =SUMIF(Decklist!F4:F150,"W/B",Decklist!A4:A150)
B18: Karlov's exile ability needs six counters, i.e. three life-gain triggers. The two combo pairs are Exquisite Blood + Sanguine Bond and Exquisite Blood + Vito / Vizkopa Guildmage.
B21: Mana Curve
B22: Mana Value | C22: Count
B23: 1 | C23: =SUMIFS(Decklist!A4:A150,Decklist!E4:E150,B23,Decklist!B4:B150,"<>Lands")
B24: 2 | C24: =SUMIFS(Decklist!A4:A150,Decklist!E4:E150,B24,Decklist!B4:B150,"<>Lands")
B25: 3 | C25: =SUMIFS(Decklist!A4:A150,Decklist!E4:E150,B25,Decklist!B4:B150,"<>Lands")
B26: 4 | C26: =SUMIFS(Decklist!A4:A150,Decklist!E4:E150,B26,Decklist!B4:B150,"<>Lands")
B27: 5 | C27: =SUMIFS(Decklist!A4:A150,Decklist!E4:E150,B27,Decklist!B4:B150,"<>Lands")
B28: 6 | C28: =SUMIFS(Decklist!A4:A150,Decklist!E4:E150,B28,Decklist!B4:B150,"<>Lands")
B29: 7 | C29: =SUMIFS(Decklist!A4:A150,Decklist!E4:E150,B29,Decklist!B4:B150,"<>Lands")
B30: 8 | C30: =SUMIFS(Decklist!A4:A150,Decklist!E4:E150,B30,Decklist!B4:B150,"<>Lands")
B33: Category Breakdown
B34: Category | C34: Count
B35: Commander | C35: =SUMIF(Decklist!B4:B150,B35,Decklist!A4:A150)
B36: Lifegain Engines | C36: =SUMIF(Decklist!B4:B150,B36,Decklist!A4:A150)
B37: Lifegain Payoffs | C37: =SUMIF(Decklist!B4:B150,B37,Decklist!A4:A150)
B38: Card Advantage | C38: =SUMIF(Decklist!B4:B150,B38,Decklist!A4:A150)
B39: Ramp & Fixing | C39: =SUMIF(Decklist!B4:B150,B39,Decklist!A4:A150)
B40: Removal & Wraths | C40: =SUMIF(Decklist!B4:B150,B40,Decklist!A4:A150)
B41: Protection & Equipment | C41: =SUMIF(Decklist!B4:B150,B41,Decklist!A4:A150)
B42: Lands | C42: =SUMIF(Decklist!B4:B150,B42,Decklist!A4:A150)
B43: Total | C43: =SUM(C35:C42)
B46: Card Type Breakdown
B47: Card Type | C47: Count
B48: Creature | C48: =SUMIF(Decklist!D4:D150,B48,Decklist!A4:A150)
B49: Planeswalker | C49: =SUMIF(Decklist!D4:D150,B49,Decklist!A4:A150)
...
