Workbook

Sheet Dashboard
B2: Lorehold, the Historian
B3: Commander Deck Dashboard & Analytics (v14)
B5: Key Deck Metrics
B6: Metric | C6: Value
B7: Total Cards | C7: =SUM(Decklist!A4:A93)
B8: Total Deck Cost (USD) | C8: =SUMPRODUCT(Decklist!A4:A92, Decklist!H4:H92)
B9: Max Mana Value | C9: =MAX(Decklist!E4:E93)
B10: Avg Mana Value (Spells) | C10: =AVERAGEIF(Decklist!B4:B92, "<>Lands", Decklist!E4:E93)
B13: Mana Curve
B14: Mana Value | C14: Count
B15: 1 | C15: =SUMIFS(Decklist!A4:A92, Decklist!E4:E92, B15, Decklist!B4:B92, "<>Lands")
B16: 2 | C16: =SUMIFS(Decklist!A4:A92, Decklist!E4:E92, B16, Decklist!B4:B92, "<>Lands")
B17: 3 | C17: =SUMIFS(Decklist!A4:A92, Decklist!E4:E92, B17, Decklist!B4:B92, "<>Lands")
B18: 4 | C18: =SUMIFS(Decklist!A4:A92, Decklist!E4:E92, B18, Decklist!B4:B92, "<>Lands")
B19: 5 | C19: =SUMIFS(Decklist!A4:A92, Decklist!E4:E92, B19, Decklist!B4:B92, "<>Lands")
B20: 6 | C20: =SUMIFS(Decklist!A4:A92, Decklist!E4:E92, B20, Decklist!B4:B92, "<>Lands")
B21: 7 | C21: =SUMIFS(Decklist!A4:A92, Decklist!E4:E92, B21, Decklist!B4:B92, "<>Lands")
B22: 8 | C22: =SUMIFS(Decklist!A4:A92, Decklist!E4:E92, B22, Decklist!B4:B92, "<>Lands")
B23: 9 | C23: =SUMIFS(Decklist!A4:A92, Decklist!E4:E92, B23, Decklist!B4:B92, "<>Lands")
B24: 10 | C24: =SUMIFS(Decklist!A4:A92, Decklist!E4:E92, B24, Decklist!B4:B92, "<>Lands")
B25: 11 | C25: =SUMIFS(Decklist!A4:A92, Decklist!E4:E92, B25, Decklist!B4:B92, "<>Lands")
B26: 12 | C26: =SUMIFS(Decklist!A4:A92, Decklist!E4:E92, B26, Decklist!B4:B92, "<>Lands")
B29: Category Breakdown
B30: Category | C30: Count
B31: Commander | C31: =SUMIF(Decklist!B4:B92, B31, Decklist!A4:A92)
B32: Massive Haymakers | C32: =SUMIF(Decklist!B4:B92, B32, Decklist!A4:A92)
B33: Support Creatures | C33: =SUMIF(Decklist!B4:B92, B33, Decklist!A4:A92)
B34: Top-Deck Engines | C34: =SUMIF(Decklist!B4:B92, B34, Decklist!A4:A92)
B35: Interaction & Protection | C35: =SUMIF(Decklist!B4:B92, B35, Decklist!A4:A92)
B36: Cross-Turn Mana | C36: =SUMIF(Decklist!B4:B92, B36, Decklist!A4:A92)
B37: Mana Accelerants | C37: =SUMIF(Decklist!B4:B92, B37, Decklist!A4:A92)
B38: Lands / Spells | C38: =SUMIF(Decklist!B4:B92, B38, Decklist!A4:A92)
B39: Lands | C39: =SUMIF(Decklist!B4:B92, B39, Decklist!A4:A92)
B41: Category Breakdown
B42: Category | C42: Count
B43: Creature | C43: =SUMIF(Decklist!D$4:D$104, B43, Decklist!A$4:A$104)
B44: Instant | C44: =SUMIF(Decklist!D$4:D$104, B44, Decklist!A$4:A$104)
B45: Sorcery | C45: =SUMIF(Decklist!D$4:D$104, B45, Decklist!A$4:A$104)
B46: Artifact | C46: =SUMIF(Decklist!D$4:D$104, B46, Decklist!A$4:A$104)
B47: Enchantment | C47: =SUMIF(Decklist!D$4:D$104, B47, Decklist!A$4:A$104)
...

Sheet Decklist
A1: Lorehold, the Historian — Comprehensive Decklist (v16)
A3: Quantity | B3: Category | C3: Card Name | D3: Card Type | E3: Mana Value | F3: Miracle Cost | G3: Key Card? | H3: Est. Cost (USD) | I3: Collection Status | J3: Notes & Strategy
A4: 1 | B4: Cross-Turn Mana | C4: Bender's Waterskin | D4: Artifact | E4: 3 | G4: Yes | H4: 1.5 | I4: Owned | J4: Untaps on every untap step.
A5: 1 | B5: Massive Haymakers | C5: Apex of Power | D5: Sorcery | E5: 10 | F5: 2 | G5: No | H5: 1 | I5: Owned | J5: Exiles top 7 to play, makes 10 mana from hand.
A6: 1 | B6: Massive Haymakers | C6: Soulfire Eruption | D6: Sorcery | E6: 9 | G6: Yes | H6: 0.45 | I6: Owned | J6: Budget mass-damage / Card draw.
A7: 1 | B7: Mana Accelerants | C7: Arcane Signet | D7: Artifact | E7: 2 | G7: No | H7: 0.5 | I7: Owned | J7: Boros fixing.
A8: 1 | B8: Mana Accelerants | C8: Boros Signet | D8: Artifact | E8: 2 | G8: No | H8: 0.5 | I8: Owned | J8: Classic signet.
A9: 1 | B9: Top-Deck Engines | C9: Library of Leng | D9: Artifact | E9: 1 | G9: Yes | H9: 2 | I9: Owned | J9: Puts discarded cards on top to immediately miracle them.
A10: 1 | B10: Top-Deck Engines | C10: Scroll Rack | D10: Artifact | E10: 2 | G10: Yes | H10: 22 | I10: Owned | J10: Perfect hand-to-deck swapping mechanism.
A11: 1 | B11: Top-Deck Engines | C11: Sensei's Divining Top | D11: Artifact | E11: 1 | G11: Yes | H11: 25 | I11: Owned | J11: Rearranges top 3 and draws on demand.
A12: 1 | B12: Mana Accelerants | C12: Sol Ring | D12: Artifact | E12: 1 | G12: Yes | H12: 1.5 | I12: Owned | J12: Fast mana.
A13: 1 | B13: Mana Accelerants | C13: Talisman of Conviction | D13: Artifact | E13: 2 | G13: No | H13: 0.5 | I13: Owned | J13: Untapped fixing.
A14: 1 | B14: Cross-Turn Mana | C14: Victory Chimes | D14: Artifact | E14: 3 | G14: Yes | H14: 1 | I14: Owned | J14: Untaps on every player's untap step for miracle responses.
A15: 1 | B15: Top-Deck Engines | C15: Dragon's Rage Channeler | D15: Creature | E15: 1 | G15: Yes | H15: 1.5 | I15: Owned | J15: Surveil 1 sets up top-deck.
A16: 1 | B16: Massive Haymakers | C16: Goliath Daydreamer | D16: Creature | E16: 4 | G16: No | H16: 0.5 | I16: Owned | J16: Large threat / haymaker.
A17: 1 | B17: Support Creatures | C17: Guttersnipe | D17: Creature | E17: 3 | G17: No | H17: 0.25 | I17: Owned | J17: Burn damage on spells.
... A40: 1 | B40: Lands | C40: Boros Garrison | D40: Land | E40: 0 | G40: No | H40: 0.25 | I40: Owned | J40: Bounce Land
A41: 1 | B41: Lands | C41: Cavern of Souls | D41: Land | E41: 0 | G41: No | H41: 40 | I41: Owned
A42: 1 | B42: Lands | C42: Clifftop Retreat | D42: Land | E42: 0 | G42: No | H42: 3.5 | I42: Owned | J42: Check Land
A43: 1 | B43: Lands | C43: Command Tower | D43: Land | E43: 0 | G43: No | H43: 0.25 | I43: Owned | J43: Multi-color Land
A44: 1 | B44: Lands | C44: Elegant Parlor | D44: Land | E44: 0 | G44: No | H44: 2.5 | I44: Owned | J44: Surveil Land
A45: 1 | B45: Lands | C45: Fabled Passage | D45: Land | E45: 0 | G45: No | H45: 6 | I45: Owned | J45: Fetch Land
A46: 1 | B46: Lands | C46: Geier Reach Sanitarium | D46: Land | E46: 0 | G46: No | H46: 1 | I46: Owned | J46: Symmetrical loot
A47: 1 | B47: Lands | C47: Mikokoro, Center of the Sea | D47: Land | E47: 0 | G47: No | H47: 3.5 | I47: Owned | J47: Symmetrical draw
A48: 6 | B48: Lands | C48: Mountain | D48: Land | E48: 0 | G48: No | H48: 0.1 | I48: Owned | J48: Basic Red
A49: 1 | B49: Lands | C49: Needleverge Pathway | D49: Land | E49: 0 | G49: No | H49: 4 | I49: Owned | J49: Pathway Land
A50: 6 | B50: Lands | C50: Plains | D50: Land | E50: 0 | G50: No | H50: 0.1 | I50: Owned | J50: Basic White
A51: 1 | B51: Lands | C51: Plaza of Heroes | D51: Land | E51: 0 | G51: No | H51: 7 | I51: Owned | J51: Commander protection
A52: 1 | B52: Lands | C52: Prismatic Vista | D52: Land | E52: 0 | G52: No | H52: 26 | I52: Owned | J52: Fetch Land
A53: 1 | B53: Lands | C53: Reliquary Tower | D53: Land | E53: 0 | G53: Yes | H53: 2.5 | I53: Owned | J53: No max hand size
... A59: 1 | B59: Lands | C59: Temple of Triumph | D59: Land | E59: 0 | G59: No | H59: 0.25 | I59: Owned | J59: Scry Land
A60: 1 | B60: Massive Haymakers | C60: Approach of the Second Sun | D60: Sorcery | E60: 7 | F60: 2 | G60: No | H60: 1.5 | I60: Owned | J60: Alternate win condition.
A61: 1 | B61: Massive Haymakers | C61: Blasphemous Act | D61: Sorcery | E61: 9 | F61: 2 | G61: No | H61: 3 | I61: Owned | J61: Ultra-cheap board wipe.
A62: 1 | B62: Interaction & Protection | C62: Borrowed Knowledge | D62: Sorcery | E62: 4 | G62: No | H62: 0.5 | I62: Owned | J62: Hand cycling.
A63: 1 | B63: Lands / Spells | C63: Emeria's Call | D63: Sorcery | E63: 7 | G63: Yes | H63: 7 | I63: Owned | J63: MDFC land / High-MV spell flip.
A64: 1 | B64: Interaction & Protection | C64: Faithless Looting | D64: Sorcery | E64: 1 | G64: No | H64: 0.5 | I64: Owned | J64: Classic filtering.
A65: 1 | B65: Interaction & Protection | C65: Gamble | D65: Sorcery | E65: 1 | G65: No | H65: 4 | I65: Owned | J65: High-risk tutor.
A66: 1 | B66: Massive Haymakers | C66: Hit the Mother Lode | D66: Sorcery | E66: 7 | G66: Yes | H66: 0.4 | I66: Owned | J66: High-MV flip & treasure cascade.
A67: 1 | B67: Massive Haymakers | C67: Improvisation Capstone | D67: Sorcery | E67: 7 | F67: 2 | G67: No | H67: 15.5 | I67: Owned | J67: Spell recursion.
A68: 1 | B68: Lands / Spells | C68: Ondu Inversion | D68: Sorcery | E68: 8 | G68: Yes | H68: 1 | I68: Owned | J68: MDFC board wipe.
...
